[2024-10-09T15:39:44.696+0000] {local_task_job_runner.py:123} INFO - ::group::Pre task execution logs
[2024-10-09T15:39:44.745+0000] {taskinstance.py:2612} INFO - Dependencies all met for dep_context=non-requeueable deps ti=<TaskInstance: example_mssql.create_country_table manual__2024-10-09T15:39:38.419495+00:00 [queued]>
[2024-10-09T15:39:44.760+0000] {taskinstance.py:2612} INFO - Dependencies all met for dep_context=requeueable deps ti=<TaskInstance: example_mssql.create_country_table manual__2024-10-09T15:39:38.419495+00:00 [queued]>
[2024-10-09T15:39:44.761+0000] {taskinstance.py:2865} INFO - Starting attempt 1 of 1
[2024-10-09T15:39:44.784+0000] {taskinstance.py:2888} INFO - Executing <Task(SQLExecuteQueryOperator): create_country_table> on 2024-10-09 15:39:38.419495+00:00
[2024-10-09T15:39:44.798+0000] {warnings.py:112} WARNING - /home/***/.local/lib/python3.12/site-packages/***/task/task_runner/standard_task_runner.py:70: DeprecationWarning: This process (pid=659) is multi-threaded, use of fork() may lead to deadlocks in the child.
  pid = os.fork()

[2024-10-09T15:39:44.801+0000] {standard_task_runner.py:72} INFO - Started process 661 to run task
[2024-10-09T15:39:44.802+0000] {standard_task_runner.py:104} INFO - Running: ['***', 'tasks', 'run', 'example_mssql', 'create_country_table', 'manual__2024-10-09T15:39:38.419495+00:00', '--job-id', '55', '--raw', '--subdir', 'DAGS_FOLDER/mssql_test1.py', '--cfg-path', '/tmp/tmpo7bglo40']
[2024-10-09T15:39:44.804+0000] {standard_task_runner.py:105} INFO - Job 55: Subtask create_country_table
[2024-10-09T15:39:44.904+0000] {task_command.py:467} INFO - Running <TaskInstance: example_mssql.create_country_table manual__2024-10-09T15:39:38.419495+00:00 [running]> on host 37a08abe3d9a
[2024-10-09T15:39:45.101+0000] {taskinstance.py:3131} INFO - Exporting env vars: AIRFLOW_CTX_DAG_OWNER='***' AIRFLOW_CTX_DAG_ID='example_mssql' AIRFLOW_CTX_TASK_ID='create_country_table' AIRFLOW_CTX_EXECUTION_DATE='2024-10-09T15:39:38.419495+00:00' AIRFLOW_CTX_TRY_NUMBER='1' AIRFLOW_CTX_DAG_RUN_ID='manual__2024-10-09T15:39:38.419495+00:00'
[2024-10-09T15:39:45.104+0000] {logging_mixin.py:190} INFO - Task instance is in running state
[2024-10-09T15:39:45.104+0000] {logging_mixin.py:190} INFO -  Previous state of the Task instance: queued
[2024-10-09T15:39:45.105+0000] {logging_mixin.py:190} INFO - Current task name:create_country_table state:running start_date:2024-10-09 15:39:44.745598+00:00
[2024-10-09T15:39:45.105+0000] {logging_mixin.py:190} INFO - Dag name:example_mssql and current dag run status:running
[2024-10-09T15:39:45.106+0000] {taskinstance.py:731} INFO - ::endgroup::
[2024-10-09T15:39:45.106+0000] {sql.py:266} INFO - Executing: 
        CREATE TABLE Country (
            country_id INT NOT NULL IDENTITY(1,1) PRIMARY KEY,
            name TEXT,
            continent TEXT
        );
        
[2024-10-09T15:39:45.124+0000] {base.py:84} INFO - Retrieving connection '***_mssql'
[2024-10-09T15:39:45.140+0000] {base.py:84} INFO - Retrieving connection '***_mssql'
[2024-10-09T15:39:45.231+0000] {sql.py:542} INFO - Running statement: 
        CREATE TABLE Country (
            country_id INT NOT NULL IDENTITY(1,1) PRIMARY KEY,
            name TEXT,
            continent TEXT
        );
        , parameters: None
[2024-10-09T15:39:45.259+0000] {taskinstance.py:3310} ERROR - Task failed with exception
Traceback (most recent call last):
  File "src/pymssql/_pymssql.pyx", line 447, in pymssql._pymssql.Cursor.execute
  File "src/pymssql/_mssql.pyx", line 1125, in pymssql._mssql.MSSQLConnection.execute_query
  File "src/pymssql/_mssql.pyx", line 1156, in pymssql._mssql.MSSQLConnection.execute_query
  File "src/pymssql/_mssql.pyx", line 1289, in pymssql._mssql.MSSQLConnection.format_and_run_query
  File "src/pymssql/_mssql.pyx", line 1855, in pymssql._mssql.check_cancel_and_raise
  File "src/pymssql/_mssql.pyx", line 1901, in pymssql._mssql.raise_MSSQLDatabaseException
pymssql._mssql.MSSQLDatabaseException: (2714, b"There is already an object named 'Country' in the database.DB-Lib error message 20018, severity 16:\nGeneral SQL Server error: Check messages from the SQL Server\n")

During handling of the above exception, another exception occurred:

Traceback (most recent call last):
  File "/home/airflow/.local/lib/python3.12/site-packages/airflow/models/taskinstance.py", line 767, in _execute_task
    result = _execute_callable(context=context, **execute_callable_kwargs)
             ^^^^^^^^^^^^^^^^^^^^^^^^^^^^^^^^^^^^^^^^^^^^^^^^^^^^^^^^^^^^^
  File "/home/airflow/.local/lib/python3.12/site-packages/airflow/models/taskinstance.py", line 733, in _execute_callable
    return ExecutionCallableRunner(
           ^^^^^^^^^^^^^^^^^^^^^^^^
  File "/home/airflow/.local/lib/python3.12/site-packages/airflow/utils/operator_helpers.py", line 252, in run
    return self.func(*args, **kwargs)
           ^^^^^^^^^^^^^^^^^^^^^^^^^^
  File "/home/airflow/.local/lib/python3.12/site-packages/airflow/models/baseoperator.py", line 406, in wrapper
    return func(self, *args, **kwargs)
           ^^^^^^^^^^^^^^^^^^^^^^^^^^^
  File "/home/airflow/.local/lib/python3.12/site-packages/airflow/providers/common/sql/operators/sql.py", line 272, in execute
    output = hook.run(
             ^^^^^^^^^
  File "/home/airflow/.local/lib/python3.12/site-packages/airflow/providers/common/sql/hooks/sql.py", line 487, in run
    self._run_command(cur, sql_statement, parameters)
  File "/home/airflow/.local/lib/python3.12/site-packages/airflow/providers/common/sql/hooks/sql.py", line 547, in _run_command
    cur.execute(sql_statement)
  File "src/pymssql/_pymssql.pyx", line 465, in pymssql._pymssql.Cursor.execute
pymssql.exceptions.OperationalError: (2714, b"There is already an object named 'Country' in the database.DB-Lib error message 20018, severity 16:\nGeneral SQL Server error: Check messages from the SQL Server\n")
[2024-10-09T15:39:45.285+0000] {logging_mixin.py:190} INFO - Task instance in failure state
[2024-10-09T15:39:45.285+0000] {logging_mixin.py:190} INFO - Task start:2024-10-09 15:39:44.745598+00:00 end:2024-10-09 15:39:45.284289+00:00 duration:0.538691
[2024-10-09T15:39:45.286+0000] {logging_mixin.py:190} INFO - Task:<Task(SQLExecuteQueryOperator): create_country_table> dag:<DAG: example_mssql> dagrun:<DagRun example_mssql @ 2024-10-09 15:39:38.419495+00:00: manual__2024-10-09T15:39:38.419495+00:00, state:running, queued_at: 2024-10-09 15:39:38.448406+00:00. externally triggered: True>
[2024-10-09T15:39:45.287+0000] {logging_mixin.py:190} INFO - Failure caused by (2714, b"There is already an object named 'Country' in the database.DB-Lib error message 20018, severity 16:\nGeneral SQL Server error: Check messages from the SQL Server\n")
[2024-10-09T15:39:45.287+0000] {taskinstance.py:1225} INFO - Marking task as FAILED. dag_id=example_mssql, task_id=create_country_table, run_id=manual__2024-10-09T15:39:38.419495+00:00, execution_date=20241009T153938, start_date=20241009T153944, end_date=20241009T153945
[2024-10-09T15:39:45.308+0000] {taskinstance.py:340} INFO - ::group::Post task execution logs
[2024-10-09T15:39:45.309+0000] {standard_task_runner.py:124} ERROR - Failed to execute job 55 for task create_country_table ((2714, b"There is already an object named 'Country' in the database.DB-Lib error message 20018, severity 16:\nGeneral SQL Server error: Check messages from the SQL Server\n"); 661)
Traceback (most recent call last):
  File "src/pymssql/_pymssql.pyx", line 447, in pymssql._pymssql.Cursor.execute
  File "src/pymssql/_mssql.pyx", line 1125, in pymssql._mssql.MSSQLConnection.execute_query
  File "src/pymssql/_mssql.pyx", line 1156, in pymssql._mssql.MSSQLConnection.execute_query
  File "src/pymssql/_mssql.pyx", line 1289, in pymssql._mssql.MSSQLConnection.format_and_run_query
  File "src/pymssql/_mssql.pyx", line 1855, in pymssql._mssql.check_cancel_and_raise
  File "src/pymssql/_mssql.pyx", line 1901, in pymssql._mssql.raise_MSSQLDatabaseException
pymssql._mssql.MSSQLDatabaseException: (2714, b"There is already an object named 'Country' in the database.DB-Lib error message 20018, severity 16:\nGeneral SQL Server error: Check messages from the SQL Server\n")

During handling of the above exception, another exception occurred:

Traceback (most recent call last):
  File "/home/airflow/.local/lib/python3.12/site-packages/airflow/task/task_runner/standard_task_runner.py", line 117, in _start_by_fork
    ret = args.func(args, dag=self.dag)
          ^^^^^^^^^^^^^^^^^^^^^^^^^^^^^
  File "/home/airflow/.local/lib/python3.12/site-packages/airflow/cli/cli_config.py", line 49, in command
    return func(*args, **kwargs)
           ^^^^^^^^^^^^^^^^^^^^^
  File "/home/airflow/.local/lib/python3.12/site-packages/airflow/utils/cli.py", line 115, in wrapper
    return f(*args, **kwargs)
           ^^^^^^^^^^^^^^^^^^
  File "/home/airflow/.local/lib/python3.12/site-packages/airflow/cli/commands/task_command.py", line 483, in task_run
    task_return_code = _run_task_by_selected_method(args, _dag, ti)
                       ^^^^^^^^^^^^^^^^^^^^^^^^^^^^^^^^^^^^^^^^^^^^
  File "/home/airflow/.local/lib/python3.12/site-packages/airflow/cli/commands/task_command.py", line 256, in _run_task_by_selected_method
    return _run_raw_task(args, ti)
           ^^^^^^^^^^^^^^^^^^^^^^^
  File "/home/airflow/.local/lib/python3.12/site-packages/airflow/cli/commands/task_command.py", line 341, in _run_raw_task
    return ti._run_raw_task(
           ^^^^^^^^^^^^^^^^^
  File "/home/airflow/.local/lib/python3.12/site-packages/airflow/utils/session.py", line 97, in wrapper
    return func(*args, session=session, **kwargs)
           ^^^^^^^^^^^^^^^^^^^^^^^^^^^^^^^^^^^^^^
  File "/home/airflow/.local/lib/python3.12/site-packages/airflow/models/taskinstance.py", line 3004, in _run_raw_task
    return _run_raw_task(
           ^^^^^^^^^^^^^^
  File "/home/airflow/.local/lib/python3.12/site-packages/airflow/models/taskinstance.py", line 273, in _run_raw_task
    TaskInstance._execute_task_with_callbacks(
  File "/home/airflow/.local/lib/python3.12/site-packages/airflow/models/taskinstance.py", line 3158, in _execute_task_with_callbacks
    result = self._execute_task(context, task_orig)
             ^^^^^^^^^^^^^^^^^^^^^^^^^^^^^^^^^^^^^^
  File "/home/airflow/.local/lib/python3.12/site-packages/airflow/models/taskinstance.py", line 3182, in _execute_task
    return _execute_task(self, context, task_orig)
           ^^^^^^^^^^^^^^^^^^^^^^^^^^^^^^^^^^^^^^^
  File "/home/airflow/.local/lib/python3.12/site-packages/airflow/models/taskinstance.py", line 767, in _execute_task
    result = _execute_callable(context=context, **execute_callable_kwargs)
             ^^^^^^^^^^^^^^^^^^^^^^^^^^^^^^^^^^^^^^^^^^^^^^^^^^^^^^^^^^^^^
  File "/home/airflow/.local/lib/python3.12/site-packages/airflow/models/taskinstance.py", line 733, in _execute_callable
    return ExecutionCallableRunner(
           ^^^^^^^^^^^^^^^^^^^^^^^^
  File "/home/airflow/.local/lib/python3.12/site-packages/airflow/utils/operator_helpers.py", line 252, in run
    return self.func(*args, **kwargs)
           ^^^^^^^^^^^^^^^^^^^^^^^^^^
  File "/home/airflow/.local/lib/python3.12/site-packages/airflow/models/baseoperator.py", line 406, in wrapper
    return func(self, *args, **kwargs)
           ^^^^^^^^^^^^^^^^^^^^^^^^^^^
  File "/home/airflow/.local/lib/python3.12/site-packages/airflow/providers/common/sql/operators/sql.py", line 272, in execute
    output = hook.run(
             ^^^^^^^^^
  File "/home/airflow/.local/lib/python3.12/site-packages/airflow/providers/common/sql/hooks/sql.py", line 487, in run
    self._run_command(cur, sql_statement, parameters)
  File "/home/airflow/.local/lib/python3.12/site-packages/airflow/providers/common/sql/hooks/sql.py", line 547, in _run_command
    cur.execute(sql_statement)
  File "src/pymssql/_pymssql.pyx", line 465, in pymssql._pymssql.Cursor.execute
pymssql.exceptions.OperationalError: (2714, b"There is already an object named 'Country' in the database.DB-Lib error message 20018, severity 16:\nGeneral SQL Server error: Check messages from the SQL Server\n")
[2024-10-09T15:39:45.344+0000] {local_task_job_runner.py:266} INFO - Task exited with return code 1
[2024-10-09T15:39:45.398+0000] {taskinstance.py:3900} INFO - 0 downstream tasks scheduled from follow-on schedule check
[2024-10-09T15:39:45.403+0000] {local_task_job_runner.py:245} INFO - ::endgroup::
