[2024-10-10T07:42:43.884+0000] {local_task_job_runner.py:123} INFO - ::group::Pre task execution logs
[2024-10-10T07:42:43.935+0000] {taskinstance.py:2612} INFO - Dependencies all met for dep_context=non-requeueable deps ti=<TaskInstance: mssql_agent_dag.execute_sql_agent_job manual__2024-10-10T07:42:28.283564+00:00 [queued]>
[2024-10-10T07:42:43.954+0000] {taskinstance.py:2612} INFO - Dependencies all met for dep_context=requeueable deps ti=<TaskInstance: mssql_agent_dag.execute_sql_agent_job manual__2024-10-10T07:42:28.283564+00:00 [queued]>
[2024-10-10T07:42:43.955+0000] {taskinstance.py:2865} INFO - Starting attempt 1 of 2
[2024-10-10T07:42:43.981+0000] {taskinstance.py:2888} INFO - Executing <Task(PythonOperator): execute_sql_agent_job> on 2024-10-10 07:42:28.283564+00:00
[2024-10-10T07:42:43.997+0000] {warnings.py:112} WARNING - /home/***/.local/lib/python3.12/site-packages/***/task/task_runner/standard_task_runner.py:70: DeprecationWarning: This process (pid=3314) is multi-threaded, use of fork() may lead to deadlocks in the child.
  pid = os.fork()

[2024-10-10T07:42:44.000+0000] {standard_task_runner.py:72} INFO - Started process 3316 to run task
[2024-10-10T07:42:44.005+0000] {standard_task_runner.py:104} INFO - Running: ['***', 'tasks', 'run', 'mssql_agent_dag', 'execute_sql_agent_job', 'manual__2024-10-10T07:42:28.283564+00:00', '--job-id', '119', '--raw', '--subdir', 'DAGS_FOLDER/mssql_test3.py', '--cfg-path', '/tmp/tmpgsewh7e9']
[2024-10-10T07:42:44.007+0000] {standard_task_runner.py:105} INFO - Job 119: Subtask execute_sql_agent_job
[2024-10-10T07:42:44.101+0000] {task_command.py:467} INFO - Running <TaskInstance: mssql_agent_dag.execute_sql_agent_job manual__2024-10-10T07:42:28.283564+00:00 [running]> on host a4f82a437ff2
[2024-10-10T07:42:44.312+0000] {taskinstance.py:3131} INFO - Exporting env vars: AIRFLOW_CTX_DAG_EMAIL='your@email.com' AIRFLOW_CTX_DAG_OWNER='***' AIRFLOW_CTX_DAG_ID='mssql_agent_dag' AIRFLOW_CTX_TASK_ID='execute_sql_agent_job' AIRFLOW_CTX_EXECUTION_DATE='2024-10-10T07:42:28.283564+00:00' AIRFLOW_CTX_TRY_NUMBER='1' AIRFLOW_CTX_DAG_RUN_ID='manual__2024-10-10T07:42:28.283564+00:00'
[2024-10-10T07:42:44.324+0000] {logging_mixin.py:190} INFO - Task instance is in running state
[2024-10-10T07:42:44.325+0000] {logging_mixin.py:190} INFO -  Previous state of the Task instance: queued
[2024-10-10T07:42:44.326+0000] {logging_mixin.py:190} INFO - Current task name:execute_sql_agent_job state:running start_date:2024-10-10 07:42:43.936045+00:00
[2024-10-10T07:42:44.327+0000] {logging_mixin.py:190} INFO - Dag name:mssql_agent_dag and current dag run status:running
[2024-10-10T07:42:44.328+0000] {taskinstance.py:731} INFO - ::endgroup::
[2024-10-10T07:42:44.664+0000] {taskinstance.py:3310} ERROR - Task failed with exception
Traceback (most recent call last):
  File "src/pymssql/_pymssql.pyx", line 429, in pymssql._pymssql.Cursor.callproc
  File "src/pymssql/_mssql.pyx", line 1816, in pymssql._mssql.MSSQLStoredProcedure.execute
  File "src/pymssql/_mssql.pyx", line 1855, in pymssql._mssql.check_cancel_and_raise
  File "src/pymssql/_mssql.pyx", line 1901, in pymssql._mssql.raise_MSSQLDatabaseException
pymssql._mssql.MSSQLDatabaseException: (22022, b'SQLServerAgent is not currently running so it cannot be notified of this action.DB-Lib error message 20018, severity 16:\nGeneral SQL Server error: Check messages from the SQL Server\n')

During handling of the above exception, another exception occurred:

Traceback (most recent call last):
  File "/home/airflow/.local/lib/python3.12/site-packages/airflow/models/taskinstance.py", line 767, in _execute_task
    result = _execute_callable(context=context, **execute_callable_kwargs)
             ^^^^^^^^^^^^^^^^^^^^^^^^^^^^^^^^^^^^^^^^^^^^^^^^^^^^^^^^^^^^^
  File "/home/airflow/.local/lib/python3.12/site-packages/airflow/models/taskinstance.py", line 733, in _execute_callable
    return ExecutionCallableRunner(
           ^^^^^^^^^^^^^^^^^^^^^^^^
  File "/home/airflow/.local/lib/python3.12/site-packages/airflow/utils/operator_helpers.py", line 252, in run
    return self.func(*args, **kwargs)
           ^^^^^^^^^^^^^^^^^^^^^^^^^^
  File "/home/airflow/.local/lib/python3.12/site-packages/airflow/models/baseoperator.py", line 406, in wrapper
    return func(self, *args, **kwargs)
           ^^^^^^^^^^^^^^^^^^^^^^^^^^^
  File "/home/airflow/.local/lib/python3.12/site-packages/airflow/operators/python.py", line 238, in execute
    return_value = self.execute_callable()
                   ^^^^^^^^^^^^^^^^^^^^^^^
  File "/home/airflow/.local/lib/python3.12/site-packages/airflow/operators/python.py", line 256, in execute_callable
    return runner.run(*self.op_args, **self.op_kwargs)
           ^^^^^^^^^^^^^^^^^^^^^^^^^^^^^^^^^^^^^^^^^^^
  File "/home/airflow/.local/lib/python3.12/site-packages/airflow/utils/operator_helpers.py", line 252, in run
    return self.func(*args, **kwargs)
           ^^^^^^^^^^^^^^^^^^^^^^^^^^
  File "/opt/airflow/dags/mssql_test3.py", line 209, in execute_sql_agent_job
    cursor.callproc('msdb.dbo.sp_start_job', (job_name,))
  File "src/pymssql/_pymssql.pyx", line 432, in pymssql._pymssql.Cursor.callproc
pymssql.exceptions.DatabaseError: (22022, b'SQLServerAgent is not currently running so it cannot be notified of this action.DB-Lib error message 20018, severity 16:\nGeneral SQL Server error: Check messages from the SQL Server\n')
[2024-10-10T07:42:44.761+0000] {logging_mixin.py:190} INFO - Task instance in failure state
[2024-10-10T07:42:44.763+0000] {logging_mixin.py:190} INFO - Task start:2024-10-10 07:42:43.936045+00:00 end:2024-10-10 07:42:44.759441+00:00 duration:0.823396
[2024-10-10T07:42:44.764+0000] {logging_mixin.py:190} INFO - Task:<Task(PythonOperator): execute_sql_agent_job> dag:<DAG: mssql_agent_dag> dagrun:<DagRun mssql_agent_dag @ 2024-10-10 07:42:28.283564+00:00: manual__2024-10-10T07:42:28.283564+00:00, state:running, queued_at: 2024-10-10 07:42:28.303540+00:00. externally triggered: True>
[2024-10-10T07:42:44.766+0000] {logging_mixin.py:190} INFO - Failure caused by (22022, b'SQLServerAgent is not currently running so it cannot be notified of this action.DB-Lib error message 20018, severity 16:\nGeneral SQL Server error: Check messages from the SQL Server\n')
[2024-10-10T07:42:44.767+0000] {taskinstance.py:1225} INFO - Marking task as UP_FOR_RETRY. dag_id=mssql_agent_dag, task_id=execute_sql_agent_job, run_id=manual__2024-10-10T07:42:28.283564+00:00, execution_date=20241010T074228, start_date=20241010T074243, end_date=20241010T074244
[2024-10-10T07:42:44.823+0000] {taskinstance.py:340} INFO - ::group::Post task execution logs
[2024-10-10T07:42:44.827+0000] {standard_task_runner.py:124} ERROR - Failed to execute job 119 for task execute_sql_agent_job ((22022, b'SQLServerAgent is not currently running so it cannot be notified of this action.DB-Lib error message 20018, severity 16:\nGeneral SQL Server error: Check messages from the SQL Server\n'); 3316)
Traceback (most recent call last):
  File "src/pymssql/_pymssql.pyx", line 429, in pymssql._pymssql.Cursor.callproc
  File "src/pymssql/_mssql.pyx", line 1816, in pymssql._mssql.MSSQLStoredProcedure.execute
  File "src/pymssql/_mssql.pyx", line 1855, in pymssql._mssql.check_cancel_and_raise
  File "src/pymssql/_mssql.pyx", line 1901, in pymssql._mssql.raise_MSSQLDatabaseException
pymssql._mssql.MSSQLDatabaseException: (22022, b'SQLServerAgent is not currently running so it cannot be notified of this action.DB-Lib error message 20018, severity 16:\nGeneral SQL Server error: Check messages from the SQL Server\n')

During handling of the above exception, another exception occurred:

Traceback (most recent call last):
  File "/home/airflow/.local/lib/python3.12/site-packages/airflow/task/task_runner/standard_task_runner.py", line 117, in _start_by_fork
    ret = args.func(args, dag=self.dag)
          ^^^^^^^^^^^^^^^^^^^^^^^^^^^^^
  File "/home/airflow/.local/lib/python3.12/site-packages/airflow/cli/cli_config.py", line 49, in command
    return func(*args, **kwargs)
           ^^^^^^^^^^^^^^^^^^^^^
  File "/home/airflow/.local/lib/python3.12/site-packages/airflow/utils/cli.py", line 115, in wrapper
    return f(*args, **kwargs)
           ^^^^^^^^^^^^^^^^^^
  File "/home/airflow/.local/lib/python3.12/site-packages/airflow/cli/commands/task_command.py", line 483, in task_run
    task_return_code = _run_task_by_selected_method(args, _dag, ti)
                       ^^^^^^^^^^^^^^^^^^^^^^^^^^^^^^^^^^^^^^^^^^^^
  File "/home/airflow/.local/lib/python3.12/site-packages/airflow/cli/commands/task_command.py", line 256, in _run_task_by_selected_method
    return _run_raw_task(args, ti)
           ^^^^^^^^^^^^^^^^^^^^^^^
  File "/home/airflow/.local/lib/python3.12/site-packages/airflow/cli/commands/task_command.py", line 341, in _run_raw_task
    return ti._run_raw_task(
           ^^^^^^^^^^^^^^^^^
  File "/home/airflow/.local/lib/python3.12/site-packages/airflow/utils/session.py", line 97, in wrapper
    return func(*args, session=session, **kwargs)
           ^^^^^^^^^^^^^^^^^^^^^^^^^^^^^^^^^^^^^^
  File "/home/airflow/.local/lib/python3.12/site-packages/airflow/models/taskinstance.py", line 3004, in _run_raw_task
    return _run_raw_task(
           ^^^^^^^^^^^^^^
  File "/home/airflow/.local/lib/python3.12/site-packages/airflow/models/taskinstance.py", line 273, in _run_raw_task
    TaskInstance._execute_task_with_callbacks(
  File "/home/airflow/.local/lib/python3.12/site-packages/airflow/models/taskinstance.py", line 3158, in _execute_task_with_callbacks
    result = self._execute_task(context, task_orig)
             ^^^^^^^^^^^^^^^^^^^^^^^^^^^^^^^^^^^^^^
  File "/home/airflow/.local/lib/python3.12/site-packages/airflow/models/taskinstance.py", line 3182, in _execute_task
    return _execute_task(self, context, task_orig)
           ^^^^^^^^^^^^^^^^^^^^^^^^^^^^^^^^^^^^^^^
  File "/home/airflow/.local/lib/python3.12/site-packages/airflow/models/taskinstance.py", line 767, in _execute_task
    result = _execute_callable(context=context, **execute_callable_kwargs)
             ^^^^^^^^^^^^^^^^^^^^^^^^^^^^^^^^^^^^^^^^^^^^^^^^^^^^^^^^^^^^^
  File "/home/airflow/.local/lib/python3.12/site-packages/airflow/models/taskinstance.py", line 733, in _execute_callable
    return ExecutionCallableRunner(
           ^^^^^^^^^^^^^^^^^^^^^^^^
  File "/home/airflow/.local/lib/python3.12/site-packages/airflow/utils/operator_helpers.py", line 252, in run
    return self.func(*args, **kwargs)
           ^^^^^^^^^^^^^^^^^^^^^^^^^^
  File "/home/airflow/.local/lib/python3.12/site-packages/airflow/models/baseoperator.py", line 406, in wrapper
    return func(self, *args, **kwargs)
           ^^^^^^^^^^^^^^^^^^^^^^^^^^^
  File "/home/airflow/.local/lib/python3.12/site-packages/airflow/operators/python.py", line 238, in execute
    return_value = self.execute_callable()
                   ^^^^^^^^^^^^^^^^^^^^^^^
  File "/home/airflow/.local/lib/python3.12/site-packages/airflow/operators/python.py", line 256, in execute_callable
    return runner.run(*self.op_args, **self.op_kwargs)
           ^^^^^^^^^^^^^^^^^^^^^^^^^^^^^^^^^^^^^^^^^^^
  File "/home/airflow/.local/lib/python3.12/site-packages/airflow/utils/operator_helpers.py", line 252, in run
    return self.func(*args, **kwargs)
           ^^^^^^^^^^^^^^^^^^^^^^^^^^
  File "/opt/airflow/dags/mssql_test3.py", line 209, in execute_sql_agent_job
    cursor.callproc('msdb.dbo.sp_start_job', (job_name,))
  File "src/pymssql/_pymssql.pyx", line 432, in pymssql._pymssql.Cursor.callproc
pymssql.exceptions.DatabaseError: (22022, b'SQLServerAgent is not currently running so it cannot be notified of this action.DB-Lib error message 20018, severity 16:\nGeneral SQL Server error: Check messages from the SQL Server\n')
[2024-10-10T07:42:44.894+0000] {local_task_job_runner.py:266} INFO - Task exited with return code 1
[2024-10-10T07:42:44.959+0000] {local_task_job_runner.py:245} INFO - ::endgroup::
