[2024-10-09T08:47:26.982+0000] {local_task_job_runner.py:123} INFO - ::group::Pre task execution logs
[2024-10-09T08:47:27.005+0000] {taskinstance.py:2612} INFO - Dependencies all met for dep_context=non-requeueable deps ti=<TaskInstance: example_mssql.create_country_table scheduled__2024-10-08T00:00:00+00:00 [queued]>
[2024-10-09T08:47:27.016+0000] {taskinstance.py:2612} INFO - Dependencies all met for dep_context=requeueable deps ti=<TaskInstance: example_mssql.create_country_table scheduled__2024-10-08T00:00:00+00:00 [queued]>
[2024-10-09T08:47:27.016+0000] {taskinstance.py:2865} INFO - Starting attempt 1 of 1
[2024-10-09T08:47:27.032+0000] {taskinstance.py:2888} INFO - Executing <Task(SQLExecuteQueryOperator): create_country_table> on 2024-10-08 00:00:00+00:00
[2024-10-09T08:47:27.043+0000] {warnings.py:112} WARNING - /home/***/.local/lib/python3.12/site-packages/***/task/task_runner/standard_task_runner.py:70: DeprecationWarning: This process (pid=447) is multi-threaded, use of fork() may lead to deadlocks in the child.
  pid = os.fork()

[2024-10-09T08:47:27.045+0000] {standard_task_runner.py:72} INFO - Started process 451 to run task
[2024-10-09T08:47:27.045+0000] {standard_task_runner.py:104} INFO - Running: ['***', 'tasks', 'run', 'example_mssql', 'create_country_table', 'scheduled__2024-10-08T00:00:00+00:00', '--job-id', '14', '--raw', '--subdir', 'DAGS_FOLDER/mssql_test1.py', '--cfg-path', '/tmp/tmp7iw14bm3']
[2024-10-09T08:47:27.046+0000] {standard_task_runner.py:105} INFO - Job 14: Subtask create_country_table
[2024-10-09T08:47:27.105+0000] {task_command.py:467} INFO - Running <TaskInstance: example_mssql.create_country_table scheduled__2024-10-08T00:00:00+00:00 [running]> on host 633f9a607934
[2024-10-09T08:47:27.211+0000] {taskinstance.py:3131} INFO - Exporting env vars: AIRFLOW_CTX_DAG_OWNER='***' AIRFLOW_CTX_DAG_ID='example_mssql' AIRFLOW_CTX_TASK_ID='create_country_table' AIRFLOW_CTX_EXECUTION_DATE='2024-10-08T00:00:00+00:00' AIRFLOW_CTX_TRY_NUMBER='1' AIRFLOW_CTX_DAG_RUN_ID='scheduled__2024-10-08T00:00:00+00:00'
[2024-10-09T08:47:27.213+0000] {logging_mixin.py:190} INFO - Task instance is in running state
[2024-10-09T08:47:27.213+0000] {logging_mixin.py:190} INFO -  Previous state of the Task instance: queued
[2024-10-09T08:47:27.213+0000] {logging_mixin.py:190} INFO - Current task name:create_country_table state:running start_date:2024-10-09 08:47:27.006335+00:00
[2024-10-09T08:47:27.215+0000] {logging_mixin.py:190} INFO - Dag name:example_mssql and current dag run status:running
[2024-10-09T08:47:27.215+0000] {taskinstance.py:731} INFO - ::endgroup::
[2024-10-09T08:47:27.215+0000] {sql.py:266} INFO - Executing: 
        CREATE TABLE Country (
            country_id INT NOT NULL IDENTITY(1,1) PRIMARY KEY,
            name TEXT,
            continent TEXT
        );
        
[2024-10-09T08:47:27.228+0000] {base.py:84} INFO - Retrieving connection '***_mssql'
[2024-10-09T08:47:27.239+0000] {base.py:84} INFO - Retrieving connection '***_mssql'
[2024-10-09T08:47:36.253+0000] {taskinstance.py:3310} ERROR - Task failed with exception
Traceback (most recent call last):
  File "src/pymssql/_pymssql.pyx", line 650, in pymssql._pymssql.connect
  File "src/pymssql/_mssql.pyx", line 2158, in pymssql._mssql.connect
  File "src/pymssql/_mssql.pyx", line 712, in pymssql._mssql.MSSQLConnection.__init__
  File "src/pymssql/_mssql.pyx", line 1884, in pymssql._mssql.maybe_raise_MSSQLDatabaseException
  File "src/pymssql/_mssql.pyx", line 1901, in pymssql._mssql.raise_MSSQLDatabaseException
pymssql._mssql.MSSQLDatabaseException: (20009, b'DB-Lib error message 20009, severity 9:\nUnable to connect: Adaptive Server is unavailable or does not exist (localhost)\nNet-Lib error during Connection refused (111)\nDB-Lib error message 20009, severity 9:\nUnable to connect: Adaptive Server is unavailable or does not exist (localhost)\nNet-Lib error during Connection refused (111)\n')

During handling of the above exception, another exception occurred:

Traceback (most recent call last):
  File "/home/airflow/.local/lib/python3.12/site-packages/airflow/models/taskinstance.py", line 767, in _execute_task
    result = _execute_callable(context=context, **execute_callable_kwargs)
             ^^^^^^^^^^^^^^^^^^^^^^^^^^^^^^^^^^^^^^^^^^^^^^^^^^^^^^^^^^^^^
  File "/home/airflow/.local/lib/python3.12/site-packages/airflow/models/taskinstance.py", line 733, in _execute_callable
    return ExecutionCallableRunner(
           ^^^^^^^^^^^^^^^^^^^^^^^^
  File "/home/airflow/.local/lib/python3.12/site-packages/airflow/utils/operator_helpers.py", line 252, in run
    return self.func(*args, **kwargs)
           ^^^^^^^^^^^^^^^^^^^^^^^^^^
  File "/home/airflow/.local/lib/python3.12/site-packages/airflow/models/baseoperator.py", line 406, in wrapper
    return func(self, *args, **kwargs)
           ^^^^^^^^^^^^^^^^^^^^^^^^^^^
  File "/home/airflow/.local/lib/python3.12/site-packages/airflow/providers/common/sql/operators/sql.py", line 272, in execute
    output = hook.run(
             ^^^^^^^^^
  File "/home/airflow/.local/lib/python3.12/site-packages/airflow/providers/common/sql/hooks/sql.py", line 452, in run
    with self._create_autocommit_connection(autocommit) as conn:
         ^^^^^^^^^^^^^^^^^^^^^^^^^^^^^^^^^^^^^^^^^^^^^^
  File "/usr/local/lib/python3.12/contextlib.py", line 137, in __enter__
    return next(self.gen)
           ^^^^^^^^^^^^^^
  File "/home/airflow/.local/lib/python3.12/site-packages/airflow/providers/common/sql/hooks/sql.py", line 574, in _create_autocommit_connection
    with closing(self.get_conn()) as conn:
                 ^^^^^^^^^^^^^^^
  File "/home/airflow/.local/lib/python3.12/site-packages/airflow/providers/microsoft/mssql/hooks/mssql.py", line 162, in get_conn
    return pymssql.connect(
           ^^^^^^^^^^^^^^^^
  File "src/pymssql/_pymssql.pyx", line 659, in pymssql._pymssql.connect
pymssql.exceptions.OperationalError: (20009, b'DB-Lib error message 20009, severity 9:\nUnable to connect: Adaptive Server is unavailable or does not exist (localhost)\nNet-Lib error during Connection refused (111)\nDB-Lib error message 20009, severity 9:\nUnable to connect: Adaptive Server is unavailable or does not exist (localhost)\nNet-Lib error during Connection refused (111)\n')
[2024-10-09T08:47:36.271+0000] {logging_mixin.py:190} INFO - Task instance in failure state
[2024-10-09T08:47:36.272+0000] {logging_mixin.py:190} INFO - Task start:2024-10-09 08:47:27.006335+00:00 end:2024-10-09 08:47:36.271025+00:00 duration:9.26469
[2024-10-09T08:47:36.272+0000] {logging_mixin.py:190} INFO - Task:<Task(SQLExecuteQueryOperator): create_country_table> dag:<DAG: example_mssql> dagrun:<DagRun example_mssql @ 2024-10-08 00:00:00+00:00: scheduled__2024-10-08T00:00:00+00:00, state:running, queued_at: 2024-10-09 08:47:20.211293+00:00. externally triggered: False>
[2024-10-09T08:47:36.272+0000] {logging_mixin.py:190} INFO - Failure caused by (20009, b'DB-Lib error message 20009, severity 9:\nUnable to connect: Adaptive Server is unavailable or does not exist (localhost)\nNet-Lib error during Connection refused (111)\nDB-Lib error message 20009, severity 9:\nUnable to connect: Adaptive Server is unavailable or does not exist (localhost)\nNet-Lib error during Connection refused (111)\n')
[2024-10-09T08:47:36.273+0000] {taskinstance.py:1225} INFO - Marking task as FAILED. dag_id=example_mssql, task_id=create_country_table, run_id=scheduled__2024-10-08T00:00:00+00:00, execution_date=20241008T000000, start_date=20241009T084727, end_date=20241009T084736
[2024-10-09T08:47:36.288+0000] {taskinstance.py:340} INFO - ::group::Post task execution logs
[2024-10-09T08:47:36.288+0000] {standard_task_runner.py:124} ERROR - Failed to execute job 14 for task create_country_table ((20009, b'DB-Lib error message 20009, severity 9:\nUnable to connect: Adaptive Server is unavailable or does not exist (localhost)\nNet-Lib error during Connection refused (111)\nDB-Lib error message 20009, severity 9:\nUnable to connect: Adaptive Server is unavailable or does not exist (localhost)\nNet-Lib error during Connection refused (111)\n'); 451)
Traceback (most recent call last):
  File "src/pymssql/_pymssql.pyx", line 650, in pymssql._pymssql.connect
  File "src/pymssql/_mssql.pyx", line 2158, in pymssql._mssql.connect
  File "src/pymssql/_mssql.pyx", line 712, in pymssql._mssql.MSSQLConnection.__init__
  File "src/pymssql/_mssql.pyx", line 1884, in pymssql._mssql.maybe_raise_MSSQLDatabaseException
  File "src/pymssql/_mssql.pyx", line 1901, in pymssql._mssql.raise_MSSQLDatabaseException
pymssql._mssql.MSSQLDatabaseException: (20009, b'DB-Lib error message 20009, severity 9:\nUnable to connect: Adaptive Server is unavailable or does not exist (localhost)\nNet-Lib error during Connection refused (111)\nDB-Lib error message 20009, severity 9:\nUnable to connect: Adaptive Server is unavailable or does not exist (localhost)\nNet-Lib error during Connection refused (111)\n')

During handling of the above exception, another exception occurred:

Traceback (most recent call last):
  File "/home/airflow/.local/lib/python3.12/site-packages/airflow/task/task_runner/standard_task_runner.py", line 117, in _start_by_fork
    ret = args.func(args, dag=self.dag)
          ^^^^^^^^^^^^^^^^^^^^^^^^^^^^^
  File "/home/airflow/.local/lib/python3.12/site-packages/airflow/cli/cli_config.py", line 49, in command
    return func(*args, **kwargs)
           ^^^^^^^^^^^^^^^^^^^^^
  File "/home/airflow/.local/lib/python3.12/site-packages/airflow/utils/cli.py", line 115, in wrapper
    return f(*args, **kwargs)
           ^^^^^^^^^^^^^^^^^^
  File "/home/airflow/.local/lib/python3.12/site-packages/airflow/cli/commands/task_command.py", line 483, in task_run
    task_return_code = _run_task_by_selected_method(args, _dag, ti)
                       ^^^^^^^^^^^^^^^^^^^^^^^^^^^^^^^^^^^^^^^^^^^^
  File "/home/airflow/.local/lib/python3.12/site-packages/airflow/cli/commands/task_command.py", line 256, in _run_task_by_selected_method
    return _run_raw_task(args, ti)
           ^^^^^^^^^^^^^^^^^^^^^^^
  File "/home/airflow/.local/lib/python3.12/site-packages/airflow/cli/commands/task_command.py", line 341, in _run_raw_task
    return ti._run_raw_task(
           ^^^^^^^^^^^^^^^^^
  File "/home/airflow/.local/lib/python3.12/site-packages/airflow/utils/session.py", line 97, in wrapper
    return func(*args, session=session, **kwargs)
           ^^^^^^^^^^^^^^^^^^^^^^^^^^^^^^^^^^^^^^
  File "/home/airflow/.local/lib/python3.12/site-packages/airflow/models/taskinstance.py", line 3004, in _run_raw_task
    return _run_raw_task(
           ^^^^^^^^^^^^^^
  File "/home/airflow/.local/lib/python3.12/site-packages/airflow/models/taskinstance.py", line 273, in _run_raw_task
    TaskInstance._execute_task_with_callbacks(
  File "/home/airflow/.local/lib/python3.12/site-packages/airflow/models/taskinstance.py", line 3158, in _execute_task_with_callbacks
    result = self._execute_task(context, task_orig)
             ^^^^^^^^^^^^^^^^^^^^^^^^^^^^^^^^^^^^^^
  File "/home/airflow/.local/lib/python3.12/site-packages/airflow/models/taskinstance.py", line 3182, in _execute_task
    return _execute_task(self, context, task_orig)
           ^^^^^^^^^^^^^^^^^^^^^^^^^^^^^^^^^^^^^^^
  File "/home/airflow/.local/lib/python3.12/site-packages/airflow/models/taskinstance.py", line 767, in _execute_task
    result = _execute_callable(context=context, **execute_callable_kwargs)
             ^^^^^^^^^^^^^^^^^^^^^^^^^^^^^^^^^^^^^^^^^^^^^^^^^^^^^^^^^^^^^
  File "/home/airflow/.local/lib/python3.12/site-packages/airflow/models/taskinstance.py", line 733, in _execute_callable
    return ExecutionCallableRunner(
           ^^^^^^^^^^^^^^^^^^^^^^^^
  File "/home/airflow/.local/lib/python3.12/site-packages/airflow/utils/operator_helpers.py", line 252, in run
    return self.func(*args, **kwargs)
           ^^^^^^^^^^^^^^^^^^^^^^^^^^
  File "/home/airflow/.local/lib/python3.12/site-packages/airflow/models/baseoperator.py", line 406, in wrapper
    return func(self, *args, **kwargs)
           ^^^^^^^^^^^^^^^^^^^^^^^^^^^
  File "/home/airflow/.local/lib/python3.12/site-packages/airflow/providers/common/sql/operators/sql.py", line 272, in execute
    output = hook.run(
             ^^^^^^^^^
  File "/home/airflow/.local/lib/python3.12/site-packages/airflow/providers/common/sql/hooks/sql.py", line 452, in run
    with self._create_autocommit_connection(autocommit) as conn:
         ^^^^^^^^^^^^^^^^^^^^^^^^^^^^^^^^^^^^^^^^^^^^^^
  File "/usr/local/lib/python3.12/contextlib.py", line 137, in __enter__
    return next(self.gen)
           ^^^^^^^^^^^^^^
  File "/home/airflow/.local/lib/python3.12/site-packages/airflow/providers/common/sql/hooks/sql.py", line 574, in _create_autocommit_connection
    with closing(self.get_conn()) as conn:
                 ^^^^^^^^^^^^^^^
  File "/home/airflow/.local/lib/python3.12/site-packages/airflow/providers/microsoft/mssql/hooks/mssql.py", line 162, in get_conn
    return pymssql.connect(
           ^^^^^^^^^^^^^^^^
  File "src/pymssql/_pymssql.pyx", line 659, in pymssql._pymssql.connect
pymssql.exceptions.OperationalError: (20009, b'DB-Lib error message 20009, severity 9:\nUnable to connect: Adaptive Server is unavailable or does not exist (localhost)\nNet-Lib error during Connection refused (111)\nDB-Lib error message 20009, severity 9:\nUnable to connect: Adaptive Server is unavailable or does not exist (localhost)\nNet-Lib error during Connection refused (111)\n')
[2024-10-09T08:47:36.314+0000] {local_task_job_runner.py:266} INFO - Task exited with return code 1
[2024-10-09T08:47:36.342+0000] {taskinstance.py:3900} INFO - 0 downstream tasks scheduled from follow-on schedule check
[2024-10-09T08:47:36.345+0000] {local_task_job_runner.py:245} INFO - ::endgroup::
[2024-10-09T08:59:07.780+0000] {local_task_job_runner.py:123} INFO - ::group::Pre task execution logs
[2024-10-09T08:59:07.812+0000] {taskinstance.py:2612} INFO - Dependencies all met for dep_context=non-requeueable deps ti=<TaskInstance: example_mssql.create_country_table scheduled__2024-10-08T00:00:00+00:00 [queued]>
[2024-10-09T08:59:07.825+0000] {taskinstance.py:2612} INFO - Dependencies all met for dep_context=requeueable deps ti=<TaskInstance: example_mssql.create_country_table scheduled__2024-10-08T00:00:00+00:00 [queued]>
[2024-10-09T08:59:07.826+0000] {taskinstance.py:2865} INFO - Starting attempt 1 of 1
[2024-10-09T08:59:07.846+0000] {taskinstance.py:2888} INFO - Executing <Task(SQLExecuteQueryOperator): create_country_table> on 2024-10-08 00:00:00+00:00
[2024-10-09T08:59:07.861+0000] {warnings.py:112} WARNING - /home/***/.local/lib/python3.12/site-packages/***/task/task_runner/standard_task_runner.py:70: DeprecationWarning: This process (pid=606) is multi-threaded, use of fork() may lead to deadlocks in the child.
  pid = os.fork()

[2024-10-09T08:59:07.864+0000] {standard_task_runner.py:72} INFO - Started process 610 to run task
[2024-10-09T08:59:07.865+0000] {standard_task_runner.py:104} INFO - Running: ['***', 'tasks', 'run', 'example_mssql', 'create_country_table', 'scheduled__2024-10-08T00:00:00+00:00', '--job-id', '18', '--raw', '--subdir', 'DAGS_FOLDER/mssql_test1.py', '--cfg-path', '/tmp/tmpbydfgyen']
[2024-10-09T08:59:07.867+0000] {standard_task_runner.py:105} INFO - Job 18: Subtask create_country_table
[2024-10-09T08:59:07.981+0000] {task_command.py:467} INFO - Running <TaskInstance: example_mssql.create_country_table scheduled__2024-10-08T00:00:00+00:00 [running]> on host 633f9a607934
[2024-10-09T08:59:08.146+0000] {taskinstance.py:3131} INFO - Exporting env vars: AIRFLOW_CTX_DAG_OWNER='***' AIRFLOW_CTX_DAG_ID='example_mssql' AIRFLOW_CTX_TASK_ID='create_country_table' AIRFLOW_CTX_EXECUTION_DATE='2024-10-08T00:00:00+00:00' AIRFLOW_CTX_TRY_NUMBER='1' AIRFLOW_CTX_DAG_RUN_ID='scheduled__2024-10-08T00:00:00+00:00'
[2024-10-09T08:59:08.149+0000] {logging_mixin.py:190} INFO - Task instance is in running state
[2024-10-09T08:59:08.150+0000] {logging_mixin.py:190} INFO -  Previous state of the Task instance: queued
[2024-10-09T08:59:08.152+0000] {logging_mixin.py:190} INFO - Current task name:create_country_table state:running start_date:2024-10-09 08:59:07.813082+00:00
[2024-10-09T08:59:08.155+0000] {logging_mixin.py:190} INFO - Dag name:example_mssql and current dag run status:running
[2024-10-09T08:59:08.161+0000] {taskinstance.py:731} INFO - ::endgroup::
[2024-10-09T08:59:08.162+0000] {sql.py:266} INFO - Executing: 
        CREATE TABLE Country (
            country_id INT NOT NULL IDENTITY(1,1) PRIMARY KEY,
            name TEXT,
            continent TEXT
        );
        
[2024-10-09T08:59:08.195+0000] {base.py:84} INFO - Retrieving connection '***_mssql'
[2024-10-09T08:59:08.219+0000] {base.py:84} INFO - Retrieving connection '***_mssql'
[2024-10-09T08:59:08.436+0000] {taskinstance.py:3310} ERROR - Task failed with exception
Traceback (most recent call last):
  File "src/pymssql/_pymssql.pyx", line 650, in pymssql._pymssql.connect
  File "src/pymssql/_mssql.pyx", line 2158, in pymssql._mssql.connect
  File "src/pymssql/_mssql.pyx", line 712, in pymssql._mssql.MSSQLConnection.__init__
  File "src/pymssql/_mssql.pyx", line 1884, in pymssql._mssql.maybe_raise_MSSQLDatabaseException
  File "src/pymssql/_mssql.pyx", line 1901, in pymssql._mssql.raise_MSSQLDatabaseException
pymssql._mssql.MSSQLDatabaseException: (18456, b"Login failed for user 'sa'.DB-Lib error message 20018, severity 14:\nGeneral SQL Server error: Check messages from the SQL Server\nDB-Lib error message 20002, severity 9:\nAdaptive Server connection failed (mssqlserver)\nDB-Lib error message 20002, severity 9:\nAdaptive Server connection failed (mssqlserver)\n")

During handling of the above exception, another exception occurred:

Traceback (most recent call last):
  File "/home/airflow/.local/lib/python3.12/site-packages/airflow/models/taskinstance.py", line 767, in _execute_task
    result = _execute_callable(context=context, **execute_callable_kwargs)
             ^^^^^^^^^^^^^^^^^^^^^^^^^^^^^^^^^^^^^^^^^^^^^^^^^^^^^^^^^^^^^
  File "/home/airflow/.local/lib/python3.12/site-packages/airflow/models/taskinstance.py", line 733, in _execute_callable
    return ExecutionCallableRunner(
           ^^^^^^^^^^^^^^^^^^^^^^^^
  File "/home/airflow/.local/lib/python3.12/site-packages/airflow/utils/operator_helpers.py", line 252, in run
    return self.func(*args, **kwargs)
           ^^^^^^^^^^^^^^^^^^^^^^^^^^
  File "/home/airflow/.local/lib/python3.12/site-packages/airflow/models/baseoperator.py", line 406, in wrapper
    return func(self, *args, **kwargs)
           ^^^^^^^^^^^^^^^^^^^^^^^^^^^
  File "/home/airflow/.local/lib/python3.12/site-packages/airflow/providers/common/sql/operators/sql.py", line 272, in execute
    output = hook.run(
             ^^^^^^^^^
  File "/home/airflow/.local/lib/python3.12/site-packages/airflow/providers/common/sql/hooks/sql.py", line 452, in run
    with self._create_autocommit_connection(autocommit) as conn:
         ^^^^^^^^^^^^^^^^^^^^^^^^^^^^^^^^^^^^^^^^^^^^^^
  File "/usr/local/lib/python3.12/contextlib.py", line 137, in __enter__
    return next(self.gen)
           ^^^^^^^^^^^^^^
  File "/home/airflow/.local/lib/python3.12/site-packages/airflow/providers/common/sql/hooks/sql.py", line 574, in _create_autocommit_connection
    with closing(self.get_conn()) as conn:
                 ^^^^^^^^^^^^^^^
  File "/home/airflow/.local/lib/python3.12/site-packages/airflow/providers/microsoft/mssql/hooks/mssql.py", line 162, in get_conn
    return pymssql.connect(
           ^^^^^^^^^^^^^^^^
  File "src/pymssql/_pymssql.pyx", line 659, in pymssql._pymssql.connect
pymssql.exceptions.OperationalError: (18456, b"Login failed for user 'sa'.DB-Lib error message 20018, severity 14:\nGeneral SQL Server error: Check messages from the SQL Server\nDB-Lib error message 20002, severity 9:\nAdaptive Server connection failed (mssqlserver)\nDB-Lib error message 20002, severity 9:\nAdaptive Server connection failed (mssqlserver)\n")
[2024-10-09T08:59:08.489+0000] {logging_mixin.py:190} INFO - Task instance in failure state
[2024-10-09T08:59:08.492+0000] {logging_mixin.py:190} INFO - Task start:2024-10-09 08:59:07.813082+00:00 end:2024-10-09 08:59:08.488654+00:00 duration:0.675572
[2024-10-09T08:59:08.493+0000] {logging_mixin.py:190} INFO - Task:<Task(SQLExecuteQueryOperator): create_country_table> dag:<DAG: example_mssql> dagrun:<DagRun example_mssql @ 2024-10-08 00:00:00+00:00: scheduled__2024-10-08T00:00:00+00:00, state:running, queued_at: 2024-10-09 08:59:04.358247+00:00. externally triggered: False>
[2024-10-09T08:59:08.493+0000] {logging_mixin.py:190} INFO - Failure caused by (18456, b"Login failed for user 'sa'.DB-Lib error message 20018, severity 14:\nGeneral SQL Server error: Check messages from the SQL Server\nDB-Lib error message 20002, severity 9:\nAdaptive Server connection failed (mssqlserver)\nDB-Lib error message 20002, severity 9:\nAdaptive Server connection failed (mssqlserver)\n")
[2024-10-09T08:59:08.497+0000] {taskinstance.py:1225} INFO - Marking task as FAILED. dag_id=example_mssql, task_id=create_country_table, run_id=scheduled__2024-10-08T00:00:00+00:00, execution_date=20241008T000000, start_date=20241009T085907, end_date=20241009T085908
[2024-10-09T08:59:08.520+0000] {taskinstance.py:340} INFO - ::group::Post task execution logs
[2024-10-09T08:59:08.523+0000] {standard_task_runner.py:124} ERROR - Failed to execute job 18 for task create_country_table ((18456, b"Login failed for user 'sa'.DB-Lib error message 20018, severity 14:\nGeneral SQL Server error: Check messages from the SQL Server\nDB-Lib error message 20002, severity 9:\nAdaptive Server connection failed (mssqlserver)\nDB-Lib error message 20002, severity 9:\nAdaptive Server connection failed (mssqlserver)\n"); 610)
Traceback (most recent call last):
  File "src/pymssql/_pymssql.pyx", line 650, in pymssql._pymssql.connect
  File "src/pymssql/_mssql.pyx", line 2158, in pymssql._mssql.connect
  File "src/pymssql/_mssql.pyx", line 712, in pymssql._mssql.MSSQLConnection.__init__
  File "src/pymssql/_mssql.pyx", line 1884, in pymssql._mssql.maybe_raise_MSSQLDatabaseException
  File "src/pymssql/_mssql.pyx", line 1901, in pymssql._mssql.raise_MSSQLDatabaseException
pymssql._mssql.MSSQLDatabaseException: (18456, b"Login failed for user 'sa'.DB-Lib error message 20018, severity 14:\nGeneral SQL Server error: Check messages from the SQL Server\nDB-Lib error message 20002, severity 9:\nAdaptive Server connection failed (mssqlserver)\nDB-Lib error message 20002, severity 9:\nAdaptive Server connection failed (mssqlserver)\n")

During handling of the above exception, another exception occurred:

Traceback (most recent call last):
  File "/home/airflow/.local/lib/python3.12/site-packages/airflow/task/task_runner/standard_task_runner.py", line 117, in _start_by_fork
    ret = args.func(args, dag=self.dag)
          ^^^^^^^^^^^^^^^^^^^^^^^^^^^^^
  File "/home/airflow/.local/lib/python3.12/site-packages/airflow/cli/cli_config.py", line 49, in command
    return func(*args, **kwargs)
           ^^^^^^^^^^^^^^^^^^^^^
  File "/home/airflow/.local/lib/python3.12/site-packages/airflow/utils/cli.py", line 115, in wrapper
    return f(*args, **kwargs)
           ^^^^^^^^^^^^^^^^^^
  File "/home/airflow/.local/lib/python3.12/site-packages/airflow/cli/commands/task_command.py", line 483, in task_run
    task_return_code = _run_task_by_selected_method(args, _dag, ti)
                       ^^^^^^^^^^^^^^^^^^^^^^^^^^^^^^^^^^^^^^^^^^^^
  File "/home/airflow/.local/lib/python3.12/site-packages/airflow/cli/commands/task_command.py", line 256, in _run_task_by_selected_method
    return _run_raw_task(args, ti)
           ^^^^^^^^^^^^^^^^^^^^^^^
  File "/home/airflow/.local/lib/python3.12/site-packages/airflow/cli/commands/task_command.py", line 341, in _run_raw_task
    return ti._run_raw_task(
           ^^^^^^^^^^^^^^^^^
  File "/home/airflow/.local/lib/python3.12/site-packages/airflow/utils/session.py", line 97, in wrapper
    return func(*args, session=session, **kwargs)
           ^^^^^^^^^^^^^^^^^^^^^^^^^^^^^^^^^^^^^^
  File "/home/airflow/.local/lib/python3.12/site-packages/airflow/models/taskinstance.py", line 3004, in _run_raw_task
    return _run_raw_task(
           ^^^^^^^^^^^^^^
  File "/home/airflow/.local/lib/python3.12/site-packages/airflow/models/taskinstance.py", line 273, in _run_raw_task
    TaskInstance._execute_task_with_callbacks(
  File "/home/airflow/.local/lib/python3.12/site-packages/airflow/models/taskinstance.py", line 3158, in _execute_task_with_callbacks
    result = self._execute_task(context, task_orig)
             ^^^^^^^^^^^^^^^^^^^^^^^^^^^^^^^^^^^^^^
  File "/home/airflow/.local/lib/python3.12/site-packages/airflow/models/taskinstance.py", line 3182, in _execute_task
    return _execute_task(self, context, task_orig)
           ^^^^^^^^^^^^^^^^^^^^^^^^^^^^^^^^^^^^^^^
  File "/home/airflow/.local/lib/python3.12/site-packages/airflow/models/taskinstance.py", line 767, in _execute_task
    result = _execute_callable(context=context, **execute_callable_kwargs)
             ^^^^^^^^^^^^^^^^^^^^^^^^^^^^^^^^^^^^^^^^^^^^^^^^^^^^^^^^^^^^^
  File "/home/airflow/.local/lib/python3.12/site-packages/airflow/models/taskinstance.py", line 733, in _execute_callable
    return ExecutionCallableRunner(
           ^^^^^^^^^^^^^^^^^^^^^^^^
  File "/home/airflow/.local/lib/python3.12/site-packages/airflow/utils/operator_helpers.py", line 252, in run
    return self.func(*args, **kwargs)
           ^^^^^^^^^^^^^^^^^^^^^^^^^^
  File "/home/airflow/.local/lib/python3.12/site-packages/airflow/models/baseoperator.py", line 406, in wrapper
    return func(self, *args, **kwargs)
           ^^^^^^^^^^^^^^^^^^^^^^^^^^^
  File "/home/airflow/.local/lib/python3.12/site-packages/airflow/providers/common/sql/operators/sql.py", line 272, in execute
    output = hook.run(
             ^^^^^^^^^
  File "/home/airflow/.local/lib/python3.12/site-packages/airflow/providers/common/sql/hooks/sql.py", line 452, in run
    with self._create_autocommit_connection(autocommit) as conn:
         ^^^^^^^^^^^^^^^^^^^^^^^^^^^^^^^^^^^^^^^^^^^^^^
  File "/usr/local/lib/python3.12/contextlib.py", line 137, in __enter__
    return next(self.gen)
           ^^^^^^^^^^^^^^
  File "/home/airflow/.local/lib/python3.12/site-packages/airflow/providers/common/sql/hooks/sql.py", line 574, in _create_autocommit_connection
    with closing(self.get_conn()) as conn:
                 ^^^^^^^^^^^^^^^
  File "/home/airflow/.local/lib/python3.12/site-packages/airflow/providers/microsoft/mssql/hooks/mssql.py", line 162, in get_conn
    return pymssql.connect(
           ^^^^^^^^^^^^^^^^
  File "src/pymssql/_pymssql.pyx", line 659, in pymssql._pymssql.connect
pymssql.exceptions.OperationalError: (18456, b"Login failed for user 'sa'.DB-Lib error message 20018, severity 14:\nGeneral SQL Server error: Check messages from the SQL Server\nDB-Lib error message 20002, severity 9:\nAdaptive Server connection failed (mssqlserver)\nDB-Lib error message 20002, severity 9:\nAdaptive Server connection failed (mssqlserver)\n")
[2024-10-09T08:59:08.574+0000] {local_task_job_runner.py:266} INFO - Task exited with return code 1
[2024-10-09T08:59:08.690+0000] {taskinstance.py:3900} INFO - 0 downstream tasks scheduled from follow-on schedule check
[2024-10-09T08:59:08.702+0000] {local_task_job_runner.py:245} INFO - ::endgroup::
